<?xml version="1.0"?>
<robot name="simple_car">
  <!-- Car body -->
  <link name="base_link">
    <visual>
      <geometry>
        <box size="1.26 1.13 0.52"/>
      </geometry>
      <material name="red">
        <color rgba="0.8 0.1 0.1 1"/>
      </material>
    </visual>
  </link>

  <!-- Front wheels -->
  <link name="front_left_wheel">
    <visual>
      <geometry>
        <cylinder length="0.05" radius="0.08"/>
      </geometry>
      <material name="black">
        <color rgba="0.1 0.1 0.1 1"/>
      </material>
    </visual>
  </link>
  <joint name="front_left_wheel_joint" type="continuous">
    <parent link="base_link"/>
    <child link="front_left_wheel"/>
    <origin xyz="0.15 0.15 0" rpy="1.5708 0 0"/>
    <axis xyz="0 0 1"/>
  </joint>

  <link name="front_right_wheel">
    <visual>
      <geometry>
        <cylinder length="0.05" radius="0.08"/>
      </geometry>
      <material name="black"/>
    </visual>
  </link>
  <joint name="front_right_wheel_joint" type="continuous">
    <parent link="base_link"/>
    <child link="front_right_wheel"/>
    <origin xyz="0.15 -0.15 0" rpy="1.5708 0 0"/>
    <axis xyz="0 0 1"/>
  </joint>

  <!-- Rear wheels -->
  <link name="rear_left_wheel">
    <visual>
      <geometry>
        <cylinder length="0.05" radius="0.08"/>
      </geometry>
      <material name="black"/>
    </visual>
  </link>
  <joint name="rear_left_wheel_joint" type="continuous">
    <parent link="base_link"/>
    <child link="rear_left_wheel"/>
    <origin xyz="-0.15 0.15 0" rpy="1.5708 0 0"/>
    <axis xyz="0 0 1"/>
  </joint>

  <link name="rear_right_wheel">
    <visual>
      <geometry>
        <cylinder length="0.05" radius="0.08"/>
      </geometry>
      <material name="black"/>
    </visual>
  </link>
  <joint name="rear_right_wheel_joint" type="continuous">
    <parent link="base_link"/>
    <child link="rear_right_wheel"/>
    <origin xyz="-0.15 -0.15 0" rpy="1.5708 0 0"/>
    <axis xyz="0 0 1"/>
  </joint>
</robot>
